[2022-02-17 23:37:48,093] {taskinstance.py:1032} INFO - Dependencies all met for <TaskInstance: load_staging_data_dag.create_users_table manual__2022-02-17T23:37:46.410595+00:00 [queued]>
[2022-02-17 23:37:48,140] {taskinstance.py:1032} INFO - Dependencies all met for <TaskInstance: load_staging_data_dag.create_users_table manual__2022-02-17T23:37:46.410595+00:00 [queued]>
[2022-02-17 23:37:48,142] {taskinstance.py:1238} INFO - 
--------------------------------------------------------------------------------
[2022-02-17 23:37:48,144] {taskinstance.py:1239} INFO - Starting attempt 1 of 1
[2022-02-17 23:37:48,146] {taskinstance.py:1240} INFO - 
--------------------------------------------------------------------------------
[2022-02-17 23:37:48,186] {taskinstance.py:1259} INFO - Executing <Task(PostgresOperator): create_users_table> on 2022-02-17 23:37:46.410595+00:00
[2022-02-17 23:37:48,202] {standard_task_runner.py:52} INFO - Started process 5828 to run task
[2022-02-17 23:37:48,218] {standard_task_runner.py:76} INFO - Running: ['***', 'tasks', 'run', 'load_staging_data_dag', 'create_users_table', 'manual__2022-02-17T23:37:46.410595+00:00', '--job-id', '27', '--raw', '--subdir', 'DAGS_FOLDER/create_staging_table.py', '--cfg-path', '/tmp/tmpzh7ilq5n', '--error-file', '/tmp/tmpkgye7uw2']
[2022-02-17 23:37:48,249] {standard_task_runner.py:77} INFO - Job 27: Subtask create_users_table
[2022-02-17 23:37:48,540] {logging_mixin.py:109} INFO - Running <TaskInstance: load_staging_data_dag.create_users_table manual__2022-02-17T23:37:46.410595+00:00 [running]> on host bd44ee7f0b09
[2022-02-17 23:37:48,704] {taskinstance.py:1426} INFO - Exporting the following env vars:
AIRFLOW_CTX_DAG_OWNER=***
AIRFLOW_CTX_DAG_ID=load_staging_data_dag
AIRFLOW_CTX_TASK_ID=create_users_table
AIRFLOW_CTX_EXECUTION_DATE=2022-02-17T23:37:46.410595+00:00
AIRFLOW_CTX_DAG_RUN_ID=manual__2022-02-17T23:37:46.410595+00:00
[2022-02-17 23:37:48,738] {base.py:79} INFO - Using connection to: id: dev. Host: 172.17.0.2, Port: 5432, Schema: public, Login: postgres, Password: ***, extra: {}
[2022-02-17 23:39:57,706] {taskinstance.py:1700} ERROR - Task failed with exception
Traceback (most recent call last):
  File "/home/airflow/.local/lib/python3.7/site-packages/airflow/models/taskinstance.py", line 1329, in _run_raw_task
    self._execute_task_with_callbacks(context)
  File "/home/airflow/.local/lib/python3.7/site-packages/airflow/models/taskinstance.py", line 1455, in _execute_task_with_callbacks
    result = self._execute_task(context, self.task)
  File "/home/airflow/.local/lib/python3.7/site-packages/airflow/models/taskinstance.py", line 1511, in _execute_task
    result = execute_callable(context=context)
  File "/home/airflow/.local/lib/python3.7/site-packages/airflow/providers/postgres/operators/postgres.py", line 69, in execute
    self.hook.run(self.sql, self.autocommit, parameters=self.parameters)
  File "/home/airflow/.local/lib/python3.7/site-packages/airflow/hooks/dbapi.py", line 198, in run
    with closing(self.get_conn()) as conn:
  File "/home/airflow/.local/lib/python3.7/site-packages/airflow/providers/postgres/hooks/postgres.py", line 115, in get_conn
    self.conn = psycopg2.connect(**conn_args)
  File "/home/airflow/.local/lib/python3.7/site-packages/psycopg2/__init__.py", line 122, in connect
    conn = _connect(dsn, connection_factory=connection_factory, **kwasync)
psycopg2.OperationalError: connection to server at "172.17.0.2", port 5432 failed: Connection timed out
	Is the server running on that host and accepting TCP/IP connections?

[2022-02-17 23:39:57,732] {taskinstance.py:1277} INFO - Marking task as FAILED. dag_id=load_staging_data_dag, task_id=create_users_table, execution_date=20220217T233746, start_date=20220217T233748, end_date=20220217T233957
[2022-02-17 23:39:57,768] {standard_task_runner.py:92} ERROR - Failed to execute job 27 for task create_users_table
Traceback (most recent call last):
  File "/home/airflow/.local/lib/python3.7/site-packages/airflow/task/task_runner/standard_task_runner.py", line 85, in _start_by_fork
    args.func(args, dag=self.dag)
  File "/home/airflow/.local/lib/python3.7/site-packages/airflow/cli/cli_parser.py", line 48, in command
    return func(*args, **kwargs)
  File "/home/airflow/.local/lib/python3.7/site-packages/airflow/utils/cli.py", line 92, in wrapper
    return f(*args, **kwargs)
  File "/home/airflow/.local/lib/python3.7/site-packages/airflow/cli/commands/task_command.py", line 298, in task_run
    _run_task_by_selected_method(args, dag, ti)
  File "/home/airflow/.local/lib/python3.7/site-packages/airflow/cli/commands/task_command.py", line 107, in _run_task_by_selected_method
    _run_raw_task(args, ti)
  File "/home/airflow/.local/lib/python3.7/site-packages/airflow/cli/commands/task_command.py", line 184, in _run_raw_task
    error_file=args.error_file,
  File "/home/airflow/.local/lib/python3.7/site-packages/airflow/utils/session.py", line 70, in wrapper
    return func(*args, session=session, **kwargs)
  File "/home/airflow/.local/lib/python3.7/site-packages/airflow/models/taskinstance.py", line 1329, in _run_raw_task
    self._execute_task_with_callbacks(context)
  File "/home/airflow/.local/lib/python3.7/site-packages/airflow/models/taskinstance.py", line 1455, in _execute_task_with_callbacks
    result = self._execute_task(context, self.task)
  File "/home/airflow/.local/lib/python3.7/site-packages/airflow/models/taskinstance.py", line 1511, in _execute_task
    result = execute_callable(context=context)
  File "/home/airflow/.local/lib/python3.7/site-packages/airflow/providers/postgres/operators/postgres.py", line 69, in execute
    self.hook.run(self.sql, self.autocommit, parameters=self.parameters)
  File "/home/airflow/.local/lib/python3.7/site-packages/airflow/hooks/dbapi.py", line 198, in run
    with closing(self.get_conn()) as conn:
  File "/home/airflow/.local/lib/python3.7/site-packages/airflow/providers/postgres/hooks/postgres.py", line 115, in get_conn
    self.conn = psycopg2.connect(**conn_args)
  File "/home/airflow/.local/lib/python3.7/site-packages/psycopg2/__init__.py", line 122, in connect
    conn = _connect(dsn, connection_factory=connection_factory, **kwasync)
psycopg2.OperationalError: connection to server at "172.17.0.2", port 5432 failed: Connection timed out
	Is the server running on that host and accepting TCP/IP connections?

[2022-02-17 23:39:57,824] {local_task_job.py:154} INFO - Task exited with return code 1
[2022-02-17 23:39:57,950] {local_task_job.py:264} INFO - 0 downstream tasks scheduled from follow-on schedule check
