[2022-02-17 23:35:54,297] {taskinstance.py:1032} INFO - Dependencies all met for <TaskInstance: load_staging_data_dag.create_users_table scheduled__2020-02-02T00:00:00+00:00 [queued]>
[2022-02-17 23:35:54,442] {taskinstance.py:1032} INFO - Dependencies all met for <TaskInstance: load_staging_data_dag.create_users_table scheduled__2020-02-02T00:00:00+00:00 [queued]>
[2022-02-17 23:35:54,450] {taskinstance.py:1238} INFO - 
--------------------------------------------------------------------------------
[2022-02-17 23:35:54,455] {taskinstance.py:1239} INFO - Starting attempt 1 of 1
[2022-02-17 23:35:54,466] {taskinstance.py:1240} INFO - 
--------------------------------------------------------------------------------
[2022-02-17 23:35:54,534] {taskinstance.py:1259} INFO - Executing <Task(PostgresOperator): create_users_table> on 2020-02-02 00:00:00+00:00
[2022-02-17 23:35:54,560] {standard_task_runner.py:52} INFO - Started process 5748 to run task
[2022-02-17 23:35:54,609] {standard_task_runner.py:76} INFO - Running: ['***', 'tasks', 'run', 'load_staging_data_dag', 'create_users_table', 'scheduled__2020-02-02T00:00:00+00:00', '--job-id', '26', '--raw', '--subdir', 'DAGS_FOLDER/create_staging_table.py', '--cfg-path', '/tmp/tmp0c_1n3xz', '--error-file', '/tmp/tmps2_y5xu7']
[2022-02-17 23:35:54,619] {standard_task_runner.py:77} INFO - Job 26: Subtask create_users_table
[2022-02-17 23:35:54,833] {logging_mixin.py:109} INFO - Running <TaskInstance: load_staging_data_dag.create_users_table scheduled__2020-02-02T00:00:00+00:00 [running]> on host bd44ee7f0b09
[2022-02-17 23:35:55,254] {taskinstance.py:1426} INFO - Exporting the following env vars:
AIRFLOW_CTX_DAG_OWNER=***
AIRFLOW_CTX_DAG_ID=load_staging_data_dag
AIRFLOW_CTX_TASK_ID=create_users_table
AIRFLOW_CTX_EXECUTION_DATE=2020-02-02T00:00:00+00:00
AIRFLOW_CTX_DAG_RUN_ID=scheduled__2020-02-02T00:00:00+00:00
[2022-02-17 23:35:55,373] {taskinstance.py:1700} ERROR - Task failed with exception
Traceback (most recent call last):
  File "/home/airflow/.local/lib/python3.7/site-packages/airflow/models/taskinstance.py", line 1329, in _run_raw_task
    self._execute_task_with_callbacks(context)
  File "/home/airflow/.local/lib/python3.7/site-packages/airflow/models/taskinstance.py", line 1455, in _execute_task_with_callbacks
    result = self._execute_task(context, self.task)
  File "/home/airflow/.local/lib/python3.7/site-packages/airflow/models/taskinstance.py", line 1511, in _execute_task
    result = execute_callable(context=context)
  File "/home/airflow/.local/lib/python3.7/site-packages/airflow/providers/postgres/operators/postgres.py", line 69, in execute
    self.hook.run(self.sql, self.autocommit, parameters=self.parameters)
  File "/home/airflow/.local/lib/python3.7/site-packages/airflow/hooks/dbapi.py", line 198, in run
    with closing(self.get_conn()) as conn:
  File "/home/airflow/.local/lib/python3.7/site-packages/airflow/providers/postgres/hooks/postgres.py", line 88, in get_conn
    conn = deepcopy(self.connection or self.get_connection(conn_id))
  File "/home/airflow/.local/lib/python3.7/site-packages/airflow/hooks/base.py", line 68, in get_connection
    conn = Connection.get_connection_from_secrets(conn_id)
  File "/home/airflow/.local/lib/python3.7/site-packages/airflow/models/connection.py", line 410, in get_connection_from_secrets
    raise AirflowNotFoundException(f"The conn_id `{conn_id}` isn't defined")
airflow.exceptions.AirflowNotFoundException: The conn_id `postgres_default` isn't defined
[2022-02-17 23:35:55,448] {taskinstance.py:1277} INFO - Marking task as FAILED. dag_id=load_staging_data_dag, task_id=create_users_table, execution_date=20200202T000000, start_date=20220217T233554, end_date=20220217T233555
[2022-02-17 23:35:55,576] {standard_task_runner.py:92} ERROR - Failed to execute job 26 for task create_users_table
Traceback (most recent call last):
  File "/home/airflow/.local/lib/python3.7/site-packages/airflow/task/task_runner/standard_task_runner.py", line 85, in _start_by_fork
    args.func(args, dag=self.dag)
  File "/home/airflow/.local/lib/python3.7/site-packages/airflow/cli/cli_parser.py", line 48, in command
    return func(*args, **kwargs)
  File "/home/airflow/.local/lib/python3.7/site-packages/airflow/utils/cli.py", line 92, in wrapper
    return f(*args, **kwargs)
  File "/home/airflow/.local/lib/python3.7/site-packages/airflow/cli/commands/task_command.py", line 298, in task_run
    _run_task_by_selected_method(args, dag, ti)
  File "/home/airflow/.local/lib/python3.7/site-packages/airflow/cli/commands/task_command.py", line 107, in _run_task_by_selected_method
    _run_raw_task(args, ti)
  File "/home/airflow/.local/lib/python3.7/site-packages/airflow/cli/commands/task_command.py", line 184, in _run_raw_task
    error_file=args.error_file,
  File "/home/airflow/.local/lib/python3.7/site-packages/airflow/utils/session.py", line 70, in wrapper
    return func(*args, session=session, **kwargs)
  File "/home/airflow/.local/lib/python3.7/site-packages/airflow/models/taskinstance.py", line 1329, in _run_raw_task
    self._execute_task_with_callbacks(context)
  File "/home/airflow/.local/lib/python3.7/site-packages/airflow/models/taskinstance.py", line 1455, in _execute_task_with_callbacks
    result = self._execute_task(context, self.task)
  File "/home/airflow/.local/lib/python3.7/site-packages/airflow/models/taskinstance.py", line 1511, in _execute_task
    result = execute_callable(context=context)
  File "/home/airflow/.local/lib/python3.7/site-packages/airflow/providers/postgres/operators/postgres.py", line 69, in execute
    self.hook.run(self.sql, self.autocommit, parameters=self.parameters)
  File "/home/airflow/.local/lib/python3.7/site-packages/airflow/hooks/dbapi.py", line 198, in run
    with closing(self.get_conn()) as conn:
  File "/home/airflow/.local/lib/python3.7/site-packages/airflow/providers/postgres/hooks/postgres.py", line 88, in get_conn
    conn = deepcopy(self.connection or self.get_connection(conn_id))
  File "/home/airflow/.local/lib/python3.7/site-packages/airflow/hooks/base.py", line 68, in get_connection
    conn = Connection.get_connection_from_secrets(conn_id)
  File "/home/airflow/.local/lib/python3.7/site-packages/airflow/models/connection.py", line 410, in get_connection_from_secrets
    raise AirflowNotFoundException(f"The conn_id `{conn_id}` isn't defined")
airflow.exceptions.AirflowNotFoundException: The conn_id `postgres_default` isn't defined
[2022-02-17 23:35:55,653] {local_task_job.py:154} INFO - Task exited with return code 1
[2022-02-17 23:35:56,065] {local_task_job.py:264} INFO - 0 downstream tasks scheduled from follow-on schedule check
