[2022-02-21 23:52:44,314] {taskinstance.py:1032} INFO - Dependencies all met for <TaskInstance: execute_bi_load.dev_to_staging manual__2022-02-21T23:52:41.704269+00:00 [queued]>
[2022-02-21 23:52:44,354] {taskinstance.py:1032} INFO - Dependencies all met for <TaskInstance: execute_bi_load.dev_to_staging manual__2022-02-21T23:52:41.704269+00:00 [queued]>
[2022-02-21 23:52:44,355] {taskinstance.py:1238} INFO - 
--------------------------------------------------------------------------------
[2022-02-21 23:52:44,356] {taskinstance.py:1239} INFO - Starting attempt 1 of 1
[2022-02-21 23:52:44,357] {taskinstance.py:1240} INFO - 
--------------------------------------------------------------------------------
[2022-02-21 23:52:44,383] {taskinstance.py:1259} INFO - Executing <Task(PythonOperator): dev_to_staging> on 2022-02-21 23:52:41.704269+00:00
[2022-02-21 23:52:44,393] {standard_task_runner.py:52} INFO - Started process 182 to run task
[2022-02-21 23:52:44,409] {standard_task_runner.py:76} INFO - Running: ['***', 'tasks', 'run', 'execute_bi_load', 'dev_to_staging', 'manual__2022-02-21T23:52:41.704269+00:00', '--job-id', '58', '--raw', '--subdir', 'DAGS_FOLDER/execute_bi_load.py', '--cfg-path', '/tmp/tmpk5gt0o5i', '--error-file', '/tmp/tmpjdgdtorl']
[2022-02-21 23:52:44,411] {standard_task_runner.py:77} INFO - Job 58: Subtask dev_to_staging
[2022-02-21 23:52:44,554] {logging_mixin.py:109} INFO - Running <TaskInstance: execute_bi_load.dev_to_staging manual__2022-02-21T23:52:41.704269+00:00 [running]> on host f20dafecb7fa
[2022-02-21 23:52:44,676] {taskinstance.py:1426} INFO - Exporting the following env vars:
AIRFLOW_CTX_DAG_OWNER=***
AIRFLOW_CTX_DAG_ID=execute_bi_load
AIRFLOW_CTX_TASK_ID=dev_to_staging
AIRFLOW_CTX_EXECUTION_DATE=2022-02-21T23:52:41.704269+00:00
AIRFLOW_CTX_DAG_RUN_ID=manual__2022-02-21T23:52:41.704269+00:00
[2022-02-21 23:52:44,759] {taskinstance.py:1700} ERROR - Task failed with exception
Traceback (most recent call last):
  File "/home/airflow/.local/lib/python3.7/site-packages/airflow/models/taskinstance.py", line 1329, in _run_raw_task
    self._execute_task_with_callbacks(context)
  File "/home/airflow/.local/lib/python3.7/site-packages/airflow/models/taskinstance.py", line 1455, in _execute_task_with_callbacks
    result = self._execute_task(context, self.task)
  File "/home/airflow/.local/lib/python3.7/site-packages/airflow/models/taskinstance.py", line 1511, in _execute_task
    result = execute_callable(context=context)
  File "/home/airflow/.local/lib/python3.7/site-packages/airflow/operators/python.py", line 174, in execute
    return_value = self.execute_callable()
  File "/home/airflow/.local/lib/python3.7/site-packages/airflow/operators/python.py", line 185, in execute_callable
    return self.python_callable(*self.op_args, **self.op_kwargs)
  File "/opt/airflow/dags/execute_bi_load.py", line 16, in copy_to_staging
    pg_dev_hook = PostgresHook.get_hook(POSTGRES_DEV_CONN_ID)
  File "/home/airflow/.local/lib/python3.7/site-packages/airflow/hooks/base.py", line 93, in get_hook
    connection = cls.get_connection(conn_id)
  File "/home/airflow/.local/lib/python3.7/site-packages/airflow/hooks/base.py", line 68, in get_connection
    conn = Connection.get_connection_from_secrets(conn_id)
  File "/home/airflow/.local/lib/python3.7/site-packages/airflow/models/connection.py", line 410, in get_connection_from_secrets
    raise AirflowNotFoundException(f"The conn_id `{conn_id}` isn't defined")
airflow.exceptions.AirflowNotFoundException: The conn_id `dev` isn't defined
[2022-02-21 23:52:44,788] {taskinstance.py:1277} INFO - Marking task as FAILED. dag_id=execute_bi_load, task_id=dev_to_staging, execution_date=20220221T235241, start_date=20220221T235244, end_date=20220221T235244
[2022-02-21 23:52:44,855] {standard_task_runner.py:92} ERROR - Failed to execute job 58 for task dev_to_staging
Traceback (most recent call last):
  File "/home/airflow/.local/lib/python3.7/site-packages/airflow/task/task_runner/standard_task_runner.py", line 85, in _start_by_fork
    args.func(args, dag=self.dag)
  File "/home/airflow/.local/lib/python3.7/site-packages/airflow/cli/cli_parser.py", line 48, in command
    return func(*args, **kwargs)
  File "/home/airflow/.local/lib/python3.7/site-packages/airflow/utils/cli.py", line 92, in wrapper
    return f(*args, **kwargs)
  File "/home/airflow/.local/lib/python3.7/site-packages/airflow/cli/commands/task_command.py", line 298, in task_run
    _run_task_by_selected_method(args, dag, ti)
  File "/home/airflow/.local/lib/python3.7/site-packages/airflow/cli/commands/task_command.py", line 107, in _run_task_by_selected_method
    _run_raw_task(args, ti)
  File "/home/airflow/.local/lib/python3.7/site-packages/airflow/cli/commands/task_command.py", line 184, in _run_raw_task
    error_file=args.error_file,
  File "/home/airflow/.local/lib/python3.7/site-packages/airflow/utils/session.py", line 70, in wrapper
    return func(*args, session=session, **kwargs)
  File "/home/airflow/.local/lib/python3.7/site-packages/airflow/models/taskinstance.py", line 1329, in _run_raw_task
    self._execute_task_with_callbacks(context)
  File "/home/airflow/.local/lib/python3.7/site-packages/airflow/models/taskinstance.py", line 1455, in _execute_task_with_callbacks
    result = self._execute_task(context, self.task)
  File "/home/airflow/.local/lib/python3.7/site-packages/airflow/models/taskinstance.py", line 1511, in _execute_task
    result = execute_callable(context=context)
  File "/home/airflow/.local/lib/python3.7/site-packages/airflow/operators/python.py", line 174, in execute
    return_value = self.execute_callable()
  File "/home/airflow/.local/lib/python3.7/site-packages/airflow/operators/python.py", line 185, in execute_callable
    return self.python_callable(*self.op_args, **self.op_kwargs)
  File "/opt/airflow/dags/execute_bi_load.py", line 16, in copy_to_staging
    pg_dev_hook = PostgresHook.get_hook(POSTGRES_DEV_CONN_ID)
  File "/home/airflow/.local/lib/python3.7/site-packages/airflow/hooks/base.py", line 93, in get_hook
    connection = cls.get_connection(conn_id)
  File "/home/airflow/.local/lib/python3.7/site-packages/airflow/hooks/base.py", line 68, in get_connection
    conn = Connection.get_connection_from_secrets(conn_id)
  File "/home/airflow/.local/lib/python3.7/site-packages/airflow/models/connection.py", line 410, in get_connection_from_secrets
    raise AirflowNotFoundException(f"The conn_id `{conn_id}` isn't defined")
airflow.exceptions.AirflowNotFoundException: The conn_id `dev` isn't defined
[2022-02-21 23:52:45,012] {local_task_job.py:154} INFO - Task exited with return code 1
[2022-02-21 23:52:45,191] {local_task_job.py:264} INFO - 0 downstream tasks scheduled from follow-on schedule check
