[2022-02-18 03:11:33,283] {taskinstance.py:1032} INFO - Dependencies all met for <TaskInstance: dev_to_staging.copy_to_staging manual__2022-02-18T03:11:31.162582+00:00 [queued]>
[2022-02-18 03:11:33,295] {taskinstance.py:1032} INFO - Dependencies all met for <TaskInstance: dev_to_staging.copy_to_staging manual__2022-02-18T03:11:31.162582+00:00 [queued]>
[2022-02-18 03:11:33,296] {taskinstance.py:1238} INFO - 
--------------------------------------------------------------------------------
[2022-02-18 03:11:33,297] {taskinstance.py:1239} INFO - Starting attempt 1 of 1
[2022-02-18 03:11:33,298] {taskinstance.py:1240} INFO - 
--------------------------------------------------------------------------------
[2022-02-18 03:11:33,320] {taskinstance.py:1259} INFO - Executing <Task(PythonOperator): copy_to_staging> on 2022-02-18 03:11:31.162582+00:00
[2022-02-18 03:11:33,327] {standard_task_runner.py:52} INFO - Started process 197 to run task
[2022-02-18 03:11:33,347] {standard_task_runner.py:76} INFO - Running: ['***', 'tasks', 'run', 'dev_to_staging', 'copy_to_staging', 'manual__2022-02-18T03:11:31.162582+00:00', '--job-id', '38', '--raw', '--subdir', 'DAGS_FOLDER/dev_to_staging.py', '--cfg-path', '/tmp/tmp671c7au9', '--error-file', '/tmp/tmp2cwtnf1l']
[2022-02-18 03:11:33,350] {standard_task_runner.py:77} INFO - Job 38: Subtask copy_to_staging
[2022-02-18 03:11:33,442] {logging_mixin.py:109} INFO - Running <TaskInstance: dev_to_staging.copy_to_staging manual__2022-02-18T03:11:31.162582+00:00 [running]> on host 51f5c68c784a
[2022-02-18 03:11:33,525] {taskinstance.py:1426} INFO - Exporting the following env vars:
AIRFLOW_CTX_DAG_OWNER=***
AIRFLOW_CTX_DAG_ID=dev_to_staging
AIRFLOW_CTX_TASK_ID=copy_to_staging
AIRFLOW_CTX_EXECUTION_DATE=2022-02-18T03:11:31.162582+00:00
AIRFLOW_CTX_DAG_RUN_ID=manual__2022-02-18T03:11:31.162582+00:00
[2022-02-18 03:11:33,539] {base.py:79} INFO - Using connection to: id: dev. Host: ***-dev, Port: 5432, Schema: ***, Login: ***, Password: ***, extra: {}
[2022-02-18 03:11:34,037] {base.py:79} INFO - Using connection to: id: staging. Host: ***-staging, Port: 5432, Schema: ***, Login: ***, Password: ***, extra: {}
[2022-02-18 03:11:34,128] {postgres.py:129} INFO - Running copy expert: COPY users TO STDOUT, filename: dump
[2022-02-18 03:11:34,139] {base.py:79} INFO - Using connection to: id: dev. Host: ***-dev, Port: 5432, Schema: ***, Login: ***, Password: ***, extra: {}
[2022-02-18 03:11:34,158] {postgres.py:129} INFO - Running copy expert: COPY users FROM STDIN, filename: dump
[2022-02-18 03:11:34,176] {base.py:79} INFO - Using connection to: id: staging. Host: ***-staging, Port: 5432, Schema: ***, Login: ***, Password: ***, extra: {}
[2022-02-18 03:11:34,193] {taskinstance.py:1700} ERROR - Task failed with exception
Traceback (most recent call last):
  File "/home/airflow/.local/lib/python3.7/site-packages/airflow/models/taskinstance.py", line 1329, in _run_raw_task
    self._execute_task_with_callbacks(context)
  File "/home/airflow/.local/lib/python3.7/site-packages/airflow/models/taskinstance.py", line 1455, in _execute_task_with_callbacks
    result = self._execute_task(context, self.task)
  File "/home/airflow/.local/lib/python3.7/site-packages/airflow/models/taskinstance.py", line 1511, in _execute_task
    result = execute_callable(context=context)
  File "/home/airflow/.local/lib/python3.7/site-packages/airflow/operators/python.py", line 174, in execute
    return_value = self.execute_callable()
  File "/home/airflow/.local/lib/python3.7/site-packages/airflow/operators/python.py", line 185, in execute_callable
    return self.python_callable(*self.op_args, **self.op_kwargs)
  File "/opt/airflow/dags/dev_to_staging.py", line 18, in copy_to_staging
    pg_staging_hook.bulk_load(table, tempFile)
  File "/home/airflow/.local/lib/python3.7/site-packages/airflow/providers/postgres/hooks/postgres.py", line 151, in bulk_load
    self.copy_expert(f"COPY {table} FROM STDIN", tmp_file)
  File "/home/airflow/.local/lib/python3.7/site-packages/airflow/providers/postgres/hooks/postgres.py", line 137, in copy_expert
    cur.copy_expert(sql, file)
psycopg2.errors.UndefinedTable: relation "users" does not exist

[2022-02-18 03:11:34,223] {taskinstance.py:1277} INFO - Marking task as FAILED. dag_id=dev_to_staging, task_id=copy_to_staging, execution_date=20220218T031131, start_date=20220218T031133, end_date=20220218T031134
[2022-02-18 03:11:34,265] {standard_task_runner.py:92} ERROR - Failed to execute job 38 for task copy_to_staging
Traceback (most recent call last):
  File "/home/airflow/.local/lib/python3.7/site-packages/airflow/task/task_runner/standard_task_runner.py", line 85, in _start_by_fork
    args.func(args, dag=self.dag)
  File "/home/airflow/.local/lib/python3.7/site-packages/airflow/cli/cli_parser.py", line 48, in command
    return func(*args, **kwargs)
  File "/home/airflow/.local/lib/python3.7/site-packages/airflow/utils/cli.py", line 92, in wrapper
    return f(*args, **kwargs)
  File "/home/airflow/.local/lib/python3.7/site-packages/airflow/cli/commands/task_command.py", line 298, in task_run
    _run_task_by_selected_method(args, dag, ti)
  File "/home/airflow/.local/lib/python3.7/site-packages/airflow/cli/commands/task_command.py", line 107, in _run_task_by_selected_method
    _run_raw_task(args, ti)
  File "/home/airflow/.local/lib/python3.7/site-packages/airflow/cli/commands/task_command.py", line 184, in _run_raw_task
    error_file=args.error_file,
  File "/home/airflow/.local/lib/python3.7/site-packages/airflow/utils/session.py", line 70, in wrapper
    return func(*args, session=session, **kwargs)
  File "/home/airflow/.local/lib/python3.7/site-packages/airflow/models/taskinstance.py", line 1329, in _run_raw_task
    self._execute_task_with_callbacks(context)
  File "/home/airflow/.local/lib/python3.7/site-packages/airflow/models/taskinstance.py", line 1455, in _execute_task_with_callbacks
    result = self._execute_task(context, self.task)
  File "/home/airflow/.local/lib/python3.7/site-packages/airflow/models/taskinstance.py", line 1511, in _execute_task
    result = execute_callable(context=context)
  File "/home/airflow/.local/lib/python3.7/site-packages/airflow/operators/python.py", line 174, in execute
    return_value = self.execute_callable()
  File "/home/airflow/.local/lib/python3.7/site-packages/airflow/operators/python.py", line 185, in execute_callable
    return self.python_callable(*self.op_args, **self.op_kwargs)
  File "/opt/airflow/dags/dev_to_staging.py", line 18, in copy_to_staging
    pg_staging_hook.bulk_load(table, tempFile)
  File "/home/airflow/.local/lib/python3.7/site-packages/airflow/providers/postgres/hooks/postgres.py", line 151, in bulk_load
    self.copy_expert(f"COPY {table} FROM STDIN", tmp_file)
  File "/home/airflow/.local/lib/python3.7/site-packages/airflow/providers/postgres/hooks/postgres.py", line 137, in copy_expert
    cur.copy_expert(sql, file)
psycopg2.errors.UndefinedTable: relation "users" does not exist

[2022-02-18 03:11:34,327] {local_task_job.py:154} INFO - Task exited with return code 1
[2022-02-18 03:11:34,371] {local_task_job.py:264} INFO - 0 downstream tasks scheduled from follow-on schedule check
